Traceback (most recent call last):
  File "C:\Users\johnw\AppData\Local\Packages\PythonSoftwareFoundation.Python.3.11_qbz5n2kfra8p0\LocalCache\local-packages\Python311\site-packages\pandas\io\parsers\python_parser.py", line 605, in _handle_usecols
    col_indices.append(usecols_key.index(col))
                       ^^^^^^^^^^^^^^^^^^^^^^
ValueError: 'name' is not in list

During handling of the above exception, another exception occurred:

Traceback (most recent call last):
  File "C:\Users\johnw\Documents\SFU\year_5\projects\CMPT473\e2\bin\csv2json.py", line 51, in <module>
    df = pd.read_csv(
         ^^^^^^^^^^^^
  File "C:\Users\johnw\AppData\Local\Packages\PythonSoftwareFoundation.Python.3.11_qbz5n2kfra8p0\LocalCache\local-packages\Python311\site-packages\pandas\io\parsers\readers.py", line 948, in read_csv
    return _read(filepath_or_buffer, kwds)
           ^^^^^^^^^^^^^^^^^^^^^^^^^^^^^^^
  File "C:\Users\johnw\AppData\Local\Packages\PythonSoftwareFoundation.Python.3.11_qbz5n2kfra8p0\LocalCache\local-packages\Python311\site-packages\pandas\io\parsers\readers.py", line 611, in _read
    parser = TextFileReader(filepath_or_buffer, **kwds)
             ^^^^^^^^^^^^^^^^^^^^^^^^^^^^^^^^^^^^^^^^^^
  File "C:\Users\johnw\AppData\Local\Packages\PythonSoftwareFoundation.Python.3.11_qbz5n2kfra8p0\LocalCache\local-packages\Python311\site-packages\pandas\io\parsers\readers.py", line 1448, in __init__
    self._engine = self._make_engine(f, self.engine)
                   ^^^^^^^^^^^^^^^^^^^^^^^^^^^^^^^^^
  File "C:\Users\johnw\AppData\Local\Packages\PythonSoftwareFoundation.Python.3.11_qbz5n2kfra8p0\LocalCache\local-packages\Python311\site-packages\pandas\io\parsers\readers.py", line 1723, in _make_engine
    return mapping[engine](f, **self.options)
           ^^^^^^^^^^^^^^^^^^^^^^^^^^^^^^^^^^
  File "C:\Users\johnw\AppData\Local\Packages\PythonSoftwareFoundation.Python.3.11_qbz5n2kfra8p0\LocalCache\local-packages\Python311\site-packages\pandas\io\parsers\python_parser.py", line 131, in __init__
    ) = self._infer_columns()
        ^^^^^^^^^^^^^^^^^^^^^
  File "C:\Users\johnw\AppData\Local\Packages\PythonSoftwareFoundation.Python.3.11_qbz5n2kfra8p0\LocalCache\local-packages\Python311\site-packages\pandas\io\parsers\python_parser.py", line 540, in _infer_columns
    columns = self._handle_usecols(
              ^^^^^^^^^^^^^^^^^^^^^
  File "C:\Users\johnw\AppData\Local\Packages\PythonSoftwareFoundation.Python.3.11_qbz5n2kfra8p0\LocalCache\local-packages\Python311\site-packages\pandas\io\parsers\python_parser.py", line 607, in _handle_usecols
    self._validate_usecols_names(self.usecols, usecols_key)
  File "C:\Users\johnw\AppData\Local\Packages\PythonSoftwareFoundation.Python.3.11_qbz5n2kfra8p0\LocalCache\local-packages\Python311\site-packages\pandas\io\parsers\base_parser.py", line 969, in _validate_usecols_names
    raise ValueError(
ValueError: Usecols do not match columns, columns expected but not found: ['name', 'id']
