Traceback (most recent call last):
  File "C:\Users\johnw\Documents\SFU\year_5\projects\CMPT473\e2\bin\csv2json.py", line 40, in <module>
    df = pd.read_csv(
         ^^^^^^^^^^^^
  File "C:\Users\johnw\AppData\Local\Packages\PythonSoftwareFoundation.Python.3.11_qbz5n2kfra8p0\LocalCache\local-packages\Python311\site-packages\pandas\io\parsers\readers.py", line 948, in read_csv
    return _read(filepath_or_buffer, kwds)
           ^^^^^^^^^^^^^^^^^^^^^^^^^^^^^^^
  File "C:\Users\johnw\AppData\Local\Packages\PythonSoftwareFoundation.Python.3.11_qbz5n2kfra8p0\LocalCache\local-packages\Python311\site-packages\pandas\io\parsers\readers.py", line 617, in _read
    return parser.read(nrows)
           ^^^^^^^^^^^^^^^^^^
  File "C:\Users\johnw\AppData\Local\Packages\PythonSoftwareFoundation.Python.3.11_qbz5n2kfra8p0\LocalCache\local-packages\Python311\site-packages\pandas\io\parsers\readers.py", line 1748, in read
    ) = self._engine.read(  # type: ignore[attr-defined]
        ^^^^^^^^^^^^^^^^^^^^^^^^^^^^^^^^^^^^^^^^^^^^^^^^
  File "C:\Users\johnw\AppData\Local\Packages\PythonSoftwareFoundation.Python.3.11_qbz5n2kfra8p0\LocalCache\local-packages\Python311\site-packages\pandas\io\parsers\python_parser.py", line 286, in read
    alldata = self._rows_to_cols(content)
              ^^^^^^^^^^^^^^^^^^^^^^^^^^^
  File "C:\Users\johnw\AppData\Local\Packages\PythonSoftwareFoundation.Python.3.11_qbz5n2kfra8p0\LocalCache\local-packages\Python311\site-packages\pandas\io\parsers\python_parser.py", line 1058, in _rows_to_cols
    self._alert_malformed(msg, row_num + 1)
  File "C:\Users\johnw\AppData\Local\Packages\PythonSoftwareFoundation.Python.3.11_qbz5n2kfra8p0\LocalCache\local-packages\Python311\site-packages\pandas\io\parsers\python_parser.py", line 779, in _alert_malformed
    raise ParserError(msg)
pandas.errors.ParserError: Expected 4 fields in line 4, saw 5
